Workbook

Sheet all
A1: experiment_num | B1: N | C1: n | D1: N0 | E1: eta | F1: E2_neighbors | G1: Level | H1: Boxes | I1: gpu_time | J1: cpu_time | K1: speedup | L1: cpu_M2L_time | M1: cpu_P2P_time | N1: Data_collection_time | O1: M2L_data_transfer | P1: GPU_M2L_time | Q1: P2P_data_transfer | R1: GPU_P2P_time | S1: update_time
A2: 1 | B2: 65536 | C2: 3 | D2: 64 | E2: 0.5 | F2: 10 | G2: 2047 | H2: 33724 | I2: 793177300 | J2: 3531683700 | K2: 4.4525779 | L2: 7137700 | M2: 175556200 | N2: 281009400 | O2: 456565600 | P2: 116500 | Q2: 297800600 | R2: 297917100 | S2: 728000 | T2: 15081400 | U2: 1200971300 | V2: 1979845300 | W2: 143200 | X2: 793177300
A3: 2 | B3: 65536 | C3: 3 | D3: 64 | E3: 0.2 | F3: 10 | G3: 2047 | H3: 321980 | I3: 4422129100 | J3: 26061148100 | K3: 5.8933485 | L3: 51612900 | M3: 212541400 | N3: 1396591600 | O3: 1609133000 | P3: 846200 | Q3: 2716616000 | R3: 2717462200 | S3: 670500 | T3: 21208100 | U3: 6752595000 | V3: 18934114500 | W3: 166900 | X3: 4422129100
A4: 3 | B4: 65536 | C4: 3 | D4: 64 | E4: 0.35 | F4: 10 | G4: 2047 | H4: 86324 | I4: 1798688400 | J4: 8175143900 | K4: 4.5450584 | L4: 17269900 | M4: 133638500 | N4: 601632700 | O4: 735271200 | P4: 186600 | Q4: 726745800 | R4: 726932400 | S4: 697500 | T4: 22467700 | U4: 2746611100 | V4: 5094834700 | W4: 142600 | X4: 1798688400
A5: 4 | B5: 65536 | C5: 3 | D5: 64 | E5: 0.5 | F5: 10 | G5: 2047 | H5: 33668 | I5: 759899900 | J5: 3535557400 | K5: 4.652662 | L5: 6268800 | M5: 147067700 | N5: 278200700 | O5: 425268400 | P5: 102000 | Q5: 296864000 | R5: 296966000 | S5: 687700 | T5: 15347800 | U5: 1163417000 | V5: 1974948500 | W5: 154000 | X5: 759899900
A6: 5 | B6: 65536 | C6: 3 | D6: 64 | E6: 0.65 | F6: 10 | G6: 2047 | H6: 11940 | I6: 456397100 | J6: 1905943200 | K6: 4.1760633 | L6: 2539800 | M6: 163811600 | N6: 134556700 | O6: 298368300 | P6: 45900 | Q6: 120841500 | R6: 120887400 | S6: 711100 | T6: 14960600 | U6: 529496400 | V6: 706189400 | W6: 145100 | X6: 456397100
A7: 6 | B7: 65536 | C7: 3 | D7: 64 | E7: 0.8 | F7: 10 | G7: 2047 | H7: 6876 | I7: 330848700 | J7: 1064127800 | K7: 3.2163578 | L7: 1802400 | M7: 142106700 | N7: 79042500 | O7: 221149200 | P7: 68100 | Q7: 74582300 | R7: 74650400 | S7: 689500 | T7: 22360800 | U7: 327323600 | V7: 404685800 | W7: 138600 | X7: 330848700
A8: 7 | B8: 65536 | C8: 3 | D8: 64 | E8: 0.95 | F8: 10 | G8: 2047 | H8: 2048 | I8: 305799000 | J8: 684244000 | K8: 2.2375613 | L8: 738900 | M8: 196093100 | N8: 49894300 | O8: 245987400 | P8: 101100 | Q8: 24853000 | R8: 24954100 | S8: 711400 | T8: 14257700 | U8: 196374900 | V8: 121178600 | W8: 136000 | X8: 305799000
A9: 8 | B9: 65536 | C9: 4 | D9: 125 | E9: 0.5 | F9: 10 | G9: 2047 | H9: 33808 | I9: 1514948000 | J9: 7146013800 | K9: 4.7170027 | L9: 5960000 | M9: 368276200 | N9: 789880400 | O9: 1158156600 | P9: 115500 | Q9: 295241300 | R9: 295356800 | S9: 711000 | T9: 23097300 | U9: 4337255100 | V9: 2005749100 | W9: 142800 | X9: 1514948000
A10: 9 | B10: 65536 | C10: 4 | D10: 125 | E10: 0.2 | F10: 10 | G10: 2047 | H10: 322648 | I10: 7611024400 | J10: 44952660600 | K10: 5.9062563 | L10: 60093700 | M10: 347593600 | N10: 4339915500 | O10: 4687509100 | P10: 850500 | Q10: 2808231400 | R10: 2809081900 | S10: 676700 | T10: 21145100 | U10: 25175461200 | V10: 18958637100 | W10: 148800 | X10: 7611024400
A11: 10 | B11: 65536 | C11: 4 | D11: 125 | E11: 0.35 | F11: 10 | G11: 2047 | H11: 86212 | I11: 3195567700 | J11: 16074099900 | K11: 5.0301234 | L11: 16309900 | M11: 287380900 | N11: 1798804100 | O11: 2086185000 | P11: 190100 | Q11: 750439600 | R11: 750629700 | S11: 713600 | T11: 20662000 | U11: 10208927500 | V11: 5065207800 | W11: 155900 | X11: 3195567700
A12: 11 | B12: 65536 | C12: 4 | D12: 125 | E12: 0.5 | F12: 10 | G12: 2047 | H12: 33752 | I12: 1721156600 | J12: 7106500100 | K12: 4.1289097 | L12: 5984300 | M12: 292941500 | N12: 784970700 | O12: 1077912200 | P12: 116600 | Q12: 295011200 | R12: 295127800 | S12: 662900 | T12: 23354800 | U12: 4354691700 | V12: 1984990200 | W12: 144500 | X12: 1721156600
A13: 12 | B13: 65536 | C13: 4 | D13: 125 | E13: 0.65 | F13: 10 | G13: 2047 | H13: 12172 | I13: 830885600 | J13: 3890499200 | K13: 4.6823524 | L13: 2949300 | M13: 284139600 | N13: 382183600 | O13: 666323200 | P13: 73100 | Q13: 107001000 | R13: 107074100 | S13: 733700 | T13: 25523100 | U13: 2044896300 | V13: 721313200 | W13: 147800 | X13: 830885600
... A476: 150 | B476: 1048576 | C476: 7 | D476: 512 | E476: 0.95 | F476: 11 | G476: 4095 | H476: 8192 | I476: 25388032300 | J476: 73090284300 | K476: 2.8789267 | L476: 1621500 | M476: 16719368400 | N476: 2263387600 | O476: 18982756000 | P476: 150500 | Q476: 4435767500 | R476: 4435918000 | S476: 8739700 | T476: 700532400 | U476: 12079931000 | V476: 35712554500 | W476: 3764200 | X476: 25388032300

Sheet clean
A1: experiment_num | B1: N | C1: n | D1: N0 | E1: eta | F1: max_level | G1: num_clus | H1: min_nei | I1: gpu_time | J1: cpu_time | K1: speedup | L1: gpu_collection_time | M1: gpu_M2L_transfer_time | N1: gpu_M2L_computation_time | O1: gpu_M2L_time | P1: gpu_P2P_transfer_time | Q1: gpu_P2P_computation_time | R1: gpu_P2P_time | S1: gpu_Update_time | T1: cpu_collection_time | U1: cpu_M2L_time | V1: cpu_P2P_time | W1: cpu_Update_time | X1: total_gpu_time
A2: 1 | B2: 65536 | C2: 3 | D2: 64 | E2: 0.5 | F2: 10 | G2: 2047 | H2: 33724 | I2: 793177300 | J2: 3531683700 | K2: 4.4525779 | L2: 7137700 | M2: 175556200 | N2: 281009400 | O2: 456565600 | P2: 116500 | Q2: 297800600 | R2: 297917100 | S2: 728000 | T2: 15081400 | U2: 1200971300 | V2: 1979845300 | W2: 143200 | X2: 793177300
A3: 2 | B3: 65536 | C3: 3 | D3: 64 | E3: 0.2 | F3: 10 | G3: 2047 | H3: 321980 | I3: 4422129100 | J3: 26061148100 | K3: 5.8933485 | L3: 51612900 | M3: 212541400 | N3: 1396591600 | O3: 1609133000 | P3: 846200 | Q3: 2716616000 | R3: 2717462200 | S3: 670500 | T3: 21208100 | U3: 6752595000 | V3: 18934114500 | W3: 166900 | X3: 4422129100
A4: 3 | B4: 65536 | C4: 3 | D4: 64 | E4: 0.35 | F4: 10 | G4: 2047 | H4: 86324 | I4: 1798688400 | J4: 8175143900 | K4: 4.5450584 | L4: 17269900 | M4: 133638500 | N4: 601632700 | O4: 735271200 | P4: 186600 | Q4: 726745800 | R4: 726932400 | S4: 697500 | T4: 22467700 | U4: 2746611100 | V4: 5094834700 | W4: 142600 | X4: 1798688400
A5: 4 | B5: 65536 | C5: 3 | D5: 64 | E5: 0.5 | F5: 10 | G5: 2047 | H5: 33668 | I5: 759899900 | J5: 3535557400 | K5: 4.652662 | L5: 6268800 | M5: 147067700 | N5: 278200700 | O5: 425268400 | P5: 102000 | Q5: 296864000 | R5: 296966000 | S5: 687700 | T5: 15347800 | U5: 1163417000 | V5: 1974948500 | W5: 154000 | X5: 759899900
A6: 5 | B6: 65536 | C6: 3 | D6: 64 | E6: 0.65 | F6: 10 | G6: 2047 | H6: 11940 | I6: 456397100 | J6: 1905943200 | K6: 4.1760633 | L6: 2539800 | M6: 163811600 | N6: 134556700 | O6: 298368300 | P6: 45900 | Q6: 120841500 | R6: 120887400 | S6: 711100 | T6: 14960600 | U6: 529496400 | V6: 706189400 | W6: 145100 | X6: 456397100
A7: 6 | B7: 65536 | C7: 3 | D7: 64 | E7: 0.8 | F7: 10 | G7: 2047 | H7: 6876 | I7: 330848700 | J7: 1064127800 | K7: 3.2163578 | L7: 1802400 | M7: 142106700 | N7: 79042500 | O7: 221149200 | P7: 68100 | Q7: 74582300 | R7: 74650400 | S7: 689500 | T7: 22360800 | U7: 327323600 | V7: 404685800 | W7: 138600 | X7: 330848700
A8: 7 | B8: 65536 | C8: 3 | D8: 64 | E8: 0.95 | F8: 10 | G8: 2047 | H8: 2048 | I8: 305799000 | J8: 684244000 | K8: 2.2375613 | L8: 738900 | M8: 196093100 | N8: 49894300 | O8: 245987400 | P8: 101100 | Q8: 24853000 | R8: 24954100 | S8: 711400 | T8: 14257700 | U8: 196374900 | V8: 121178600 | W8: 136000 | X8: 305799000
A9: 8 | B9: 65536 | C9: 4 | D9: 125 | E9: 0.5 | F9: 10 | G9: 2047 | H9: 33808 | I9: 1514948000 | J9: 7146013800 | K9: 4.7170027 | L9: 5960000 | M9: 368276200 | N9: 789880400 | O9: 1158156600 | P9: 115500 | Q9: 295241300 | R9: 295356800 | S9: 711000 | T9: 23097300 | U9: 4337255100 | V9: 2005749100 | W9: 142800 | X9: 1514948000
A10: 9 | B10: 65536 | C10: 4 | D10: 125 | E10: 0.2 | F10: 10 | G10: 2047 | H10: 322648 | I10: 7611024400 | J10: 44952660600 | K10: 5.9062563 | L10: 60093700 | M10: 347593600 | N10: 4339915500 | O10: 4687509100 | P10: 850500 | Q10: 2808231400 | R10: 2809081900 | S10: 676700 | T10: 21145100 | U10: 25175461200 | V10: 18958637100 | W10: 148800 | X10: 7611024400
A11: 10 | B11: 65536 | C11: 4 | D11: 125 | E11: 0.35 | F11: 10 | G11: 2047 | H11: 86212 | I11: 3195567700 | J11: 16074099900 | K11: 5.0301234 | L11: 16309900 | M11: 287380900 | N11: 1798804100 | O11: 2086185000 | P11: 190100 | Q11: 750439600 | R11: 750629700 | S11: 713600 | T11: 20662000 | U11: 10208927500 | V11: 5065207800 | W11: 155900 | X11: 3195567700
A12: 11 | B12: 65536 | C12: 4 | D12: 125 | E12: 0.5 | F12: 10 | G12: 2047 | H12: 33752 | I12: 1721156600 | J12: 7106500100 | K12: 4.1289097 | L12: 5984300 | M12: 292941500 | N12: 784970700 | O12: 1077912200 | P12: 116600 | Q12: 295011200 | R12: 295127800 | S12: 662900 | T12: 23354800 | U12: 4354691700 | V12: 1984990200 | W12: 144500 | X12: 1721156600
A13: 12 | B13: 65536 | C13: 4 | D13: 125 | E13: 0.65 | F13: 10 | G13: 2047 | H13: 12172 | I13: 830885600 | J13: 3890499200 | K13: 4.6823524 | L13: 2949300 | M13: 284139600 | N13: 382183600 | O13: 666323200 | P13: 73100 | Q13: 107001000 | R13: 107074100 | S13: 733700 | T13: 25523100 | U13: 2044896300 | V13: 721313200 | W13: 147800 | X13: 830885600
... A476: 150 | B476: 1048576 | C476: 7 | D476: 512 | E476: 0.95 | F476: 11 | G476: 4095 | H476: 8192 | I476: 25388032300 | J476: 73090284300 | K476: 2.8789267 | L476: 1621500 | M476: 16719368400 | N476: 2263387600 | O476: 18982756000 | P476: 150500 | Q476: 4435767500 | R476: 4435918000 | S476: 8739700 | T476: 700532400 | U476: 12079931000 | V476: 35712554500 | W476: 3764200 | X476: 25388032300

Sheet avg
A1: N | B1: n | C1: N0 | D1: eta | E1: max_level | F1: num_clus | G1: min_nei | H1: gpu_time | I1: cpu_time | J1: speedup | K1: gpu_collection_time | L1: gpu_M2L_transfer_time | M1: gpu_M2L_computation_time | N1: gpu_M2L_time | O1: gpu_P2P_transfer_time | P1: gpu_P2P_computation_time | Q1: gpu_P2P_time | R1: gpu_Update_time | S1: gpu others FF | T1: cpu_collection_time | U1: cpu_M2L_time | V1: cpu_P2P_time | W1: cpu_Update_time | X1: CPU others FF | Y1: total_gpu_time
A2: 65536 | B2: 4 | C2: 125 | D2: 0.95 | E2: 10 | F2: =AVERAGEIFS(clean!G$2:G$998,clean!$B$2:$B$998,$A2,clean!$C$2:$C$998,$B2,clean!$D$2:$D$998,$C2,clean!$E$2:$E$998,$D2,clean!$F$2:$F$998,$E2) -> 2047 | G2: =AVERAGEIFS(clean!H$2:H$998,clean!$B$2:$B$998,$A2,clean!$C$2:$C$998,$B2,clean!$D$2:$D$998,$C2,clean!$E$2:$E$998,$D2,clean!$F$2:$F$998,$E2) -> 2052 | H2: =AVERAGEIFS(clean!I$2:I$998,clean!$B$2:$B$998,$A2,clean!$C$2:$C$998,$B2,clean!$D$2:$D$998,$C2,clean!$E$2:$E$998,$D2,clean!$F$2:$F$998,$E2) -> 5.5375593e+08 | I2: =AVERAGEIFS(clean!J$2:J$998,clean!$B$2:$B$998,$A2,clean!$C$2:$C$998,$B2,clean!$D$2:$D$998,$C2,clean!$E$2:$E$998,$D2,clean!$F$2:$F$998,$E2) -> 1.6449164e+09 | J2: =AVERAGEIFS(clean!K$2:K$998,clean!$B$2:$B$998,$A2,clean!$C$2:$C$998,$B2,clean!$D$2:$D$998,$C2,clean!$E$2:$E$998,$D2,clean!$F$2:$F$998,$E2) -> 2.9780568 | K2: =AVERAGEIFS(clean!L$2:L$998,clean!$B$2:$B$998,$A2,clean!$C$2:$C$998,$B2,clean!$D$2:$D$998,$C2,clean!$E$2:$E$998,$D2,clean!$F$2:$F$998,$E2) -> 782133.33 | L2: =AVERAGEIFS(clean!M$2:M$998,clean!$B$2:$B$998,$A2,clean!$C$2:$C$998,$B2,clean!$D$2:$D$998,$C2,clean!$E$2:$E$998,$D2,clean!$F$2:$F$998,$E2) -> 3.2412413e+08 | M2: =AVERAGEIFS(clean!N$2:N$998,clean!$B$2:$B$998,$A2,clean!$C$2:$C$998,$B2,clean!$D$2:$D$998,$C2,clean!$E$2:$E$998,$D2,clean!$F$2:$F$998,$E2) -> 150198300 | ... R2: =AVERAGEIFS(clean!S$2:S$998,clean!$B$2:$B$998,$A2,clean!$C$2:$C$998,$B2,clean!$D$2:$D$998,$C2,clean!$E$2:$E$998,$D2,clean!$F$2:$F$998,$E2) -> 715166.67 | S2: =H2-K2-N2-Q2-R2 -> 56425600 | T2: =AVERAGEIFS(clean!T$2:T$998,clean!$B$2:$B$998,$A2,clean!$C$2:$C$998,$B2,clean!$D$2:$D$998,$C2,clean!$E$2:$E$998,$D2,clean!$F$2:$F$998,$E2) -> 24111600 | U2: =AVERAGEIFS(clean!U$2:U$998,clean!$B$2:$B$998,$A2,clean!$C$2:$C$998,$B2,clean!$D$2:$D$998,$C2,clean!$E$2:$E$998,$D2,clean!$F$2:$F$998,$E2) -> 7.4086587e+08 | V2: =AVERAGEIFS(clean!V$2:V$998,clean!$B$2:$B$998,$A2,clean!$C$2:$C$998,$B2,clean!$D$2:$D$998,$C2,clean!$E$2:$E$998,$D2,clean!$F$2:$F$998,$E2) -> 129092800 | W2: =AVERAGEIFS(clean!W$2:W$998,clean!$B$2:$B$998,$A2,clean!$C$2:$C$998,$B2,clean!$D$2:$D$998,$C2,clean!$E$2:$E$998,$D2,clean!$F$2:$F$998,$E2) -> 151833.33 | X2: =I2-T2-U2-V2-W2 -> 7.5069433e+08 | Y2: =AVERAGEIFS(clean!X$2:X$998,clean!$B$2:$B$998,$A2,clean!$C$2:$C$998,$B2,clean!$D$2:$D$998,$C2,clean!$E$2:$E$998,$D2,clean!$F$2:$F$998,$E2) -> 5.5375593e+08
A3: 65536 | B3: 3 | C3: 64 | D3: 0.95 | E3: 10 | F3: =AVERAGEIFS(clean!G$2:G$998,clean!$B$2:$B$998,$A3,clean!$C$2:$C$998,$B3,clean!$D$2:$D$998,$C3,clean!$E$2:$E$998,$D3,clean!$F$2:$F$998,$E3) -> 2047 | G3: =AVERAGEIFS(clean!H$2:H$998,clean!$B$2:$B$998,$A3,clean!$C$2:$C$998,$B3,clean!$D$2:$D$998,$C3,clean!$E$2:$E$998,$D3,clean!$F$2:$F$998,$E3) -> 2049.3333 | H3: =AVERAGEIFS(clean!I$2:I$998,clean!$B$2:$B$998,$A3,clean!$C$2:$C$998,$B3,clean!$D$2:$D$998,$C3,clean!$E$2:$E$998,$D3,clean!$F$2:$F$998,$E3) -> 3.0051907e+08 | I3: =AVERAGEIFS(clean!J$2:J$998,clean!$B$2:$B$998,$A3,clean!$C$2:$C$998,$B3,clean!$D$2:$D$998,$C3,clean!$E$2:$E$998,$D3,clean!$F$2:$F$998,$E3) -> 7.9890707e+08 | J3: =AVERAGEIFS(clean!K$2:K$998,clean!$B$2:$B$998,$A3,clean!$C$2:$C$998,$B3,clean!$D$2:$D$998,$C3,clean!$E$2:$E$998,$D3,clean!$F$2:$F$998,$E3) -> 2.6687413 | K3: =AVERAGEIFS(clean!L$2:L$998,clean!$B$2:$B$998,$A3,clean!$C$2:$C$998,$B3,clean!$D$2:$D$998,$C3,clean!$E$2:$E$998,$D3,clean!$F$2:$F$998,$E3) -> 745333.33 | L3: =AVERAGEIFS(clean!M$2:M$998,clean!$B$2:$B$998,$A3,clean!$C$2:$C$998,$B3,clean!$D$2:$D$998,$C3,clean!$E$2:$E$998,$D3,clean!$F$2:$F$998,$E3) -> 1.9064713e+08 | M3: =AVERAGEIFS(clean!N$2:N$998,clean!$B$2:$B$998,$A3,clean!$C$2:$C$998,$B3,clean!$D$2:$D$998,$C3,clean!$E$2:$E$998,$D3,clean!$F$2:$F$998,$E3) -> 49881800 | ... R3: =AVERAGEIFS(clean!S$2:S$998,clean!$B$2:$B$998,$A3,clean!$C$2:$C$998,$B3,clean!$D$2:$D$998,$C3,clean!$E$2:$E$998,$D3,clean!$F$2:$F$998,$E3) -> 710800 | S3: =H3-K3-N3-Q3-R3 -> 33655900 | T3: =AVERAGEIFS(clean!T$2:T$998,clean!$B$2:$B$998,$A3,clean!$C$2:$C$998,$B3,clean!$D$2:$D$998,$C3,clean!$E$2:$E$998,$D3,clean!$F$2:$F$998,$E3) -> 14415300 | U3: =AVERAGEIFS(clean!U$2:U$998,clean!$B$2:$B$998,$A3,clean!$C$2:$C$998,$B3,clean!$D$2:$D$998,$C3,clean!$E$2:$E$998,$D3,clean!$F$2:$F$998,$E3) -> 2.0674007e+08 | V3: =AVERAGEIFS(clean!V$2:V$998,clean!$B$2:$B$998,$A3,clean!$C$2:$C$998,$B3,clean!$D$2:$D$998,$C3,clean!$E$2:$E$998,$D3,clean!$F$2:$F$998,$E3) -> 1.2315737e+08 | W3: =AVERAGEIFS(clean!W$2:W$998,clean!$B$2:$B$998,$A3,clean!$C$2:$C$998,$B3,clean!$D$2:$D$998,$C3,clean!$E$2:$E$998,$D3,clean!$F$2:$F$998,$E3) -> 153333.33 | X3: =I3-T3-U3-V3-W3 -> 454441000 | Y3: =AVERAGEIFS(clean!X$2:X$998,clean!$B$2:$B$998,$A3,clean!$C$2:$C$998,$B3,clean!$D$2:$D$998,$C3,clean!$E$2:$E$998,$D3,clean!$F$2:$F$998,$E3) -> 3.0051907e+08
A4: 65536 | B4: 4 | C4: 125 | D4: 0.8 | E4: 10 | F4: =AVERAGEIFS(clean!G$2:G$998,clean!$B$2:$B$998,$A4,clean!$C$2:$C$998,$B4,clean!$D$2:$D$998,$C4,clean!$E$2:$E$998,$D4,clean!$F$2:$F$998,$E4) -> 2047 | G4: =AVERAGEIFS(clean!H$2:H$998,clean!$B$2:$B$998,$A4,clean!$C$2:$C$998,$B4,clean!$D$2:$D$998,$C4,clean!$E$2:$E$998,$D4,clean!$F$2:$F$998,$E4) -> 6705.3333 | H4: =AVERAGEIFS(clean!I$2:I$998,clean!$B$2:$B$998,$A4,clean!$C$2:$C$998,$B4,clean!$D$2:$D$998,$C4,clean!$E$2:$E$998,$D4,clean!$F$2:$F$998,$E4) -> 680044100 | I4: =AVERAGEIFS(clean!J$2:J$998,clean!$B$2:$B$998,$A4,clean!$C$2:$C$998,$B4,clean!$D$2:$D$998,$C4,clean!$E$2:$E$998,$D4,clean!$F$2:$F$998,$E4) -> 2.4755987e+09 | J4: =AVERAGEIFS(clean!K$2:K$998,clean!$B$2:$B$998,$A4,clean!$C$2:$C$998,$B4,clean!$D$2:$D$998,$C4,clean!$E$2:$E$998,$D4,clean!$F$2:$F$998,$E4) -> 3.6515359 | K4: =AVERAGEIFS(clean!L$2:L$998,clean!$B$2:$B$998,$A4,clean!$C$2:$C$998,$B4,clean!$D$2:$D$998,$C4,clean!$E$2:$E$998,$D4,clean!$F$2:$F$998,$E4) -> 1560800 | L4: =AVERAGEIFS(clean!M$2:M$998,clean!$B$2:$B$998,$A4,clean!$C$2:$C$998,$B4,clean!$D$2:$D$998,$C4,clean!$E$2:$E$998,$D4,clean!$F$2:$F$998,$E4) -> 3.2401627e+08 | M4: =AVERAGEIFS(clean!N$2:N$998,clean!$B$2:$B$998,$A4,clean!$C$2:$C$998,$B4,clean!$D$2:$D$998,$C4,clean!$E$2:$E$998,$D4,clean!$F$2:$F$998,$E4) -> 234536200 | ... R4: =AVERAGEIFS(clean!S$2:S$998,clean!$B$2:$B$998,$A4,clean!$C$2:$C$998,$B4,clean!$D$2:$D$998,$C4,clean!$E$2:$E$998,$D4,clean!$F$2:$F$998,$E4) -> 733766.67 | S4: =H4-K4-N4-Q4-R4 -> 55262833 | T4: =AVERAGEIFS(clean!T$2:T$998,clean!$B$2:$B$998,$A4,clean!$C$2:$C$998,$B4,clean!$D$2:$D$998,$C4,clean!$E$2:$E$998,$D4,clean!$F$2:$F$998,$E4) -> 21572167 | U4: =AVERAGEIFS(clean!U$2:U$998,clean!$B$2:$B$998,$A4,clean!$C$2:$C$998,$B4,clean!$D$2:$D$998,$C4,clean!$E$2:$E$998,$D4,clean!$F$2:$F$998,$E4) -> 1201428500 | V4: =AVERAGEIFS(clean!V$2:V$998,clean!$B$2:$B$998,$A4,clean!$C$2:$C$998,$B4,clean!$D$2:$D$998,$C4,clean!$E$2:$E$998,$D4,clean!$F$2:$F$998,$E4) -> 3.9707557e+08 | W4: =AVERAGEIFS(clean!W$2:W$998,clean!$B$2:$B$998,$A4,clean!$C$2:$C$998,$B4,clean!$D$2:$D$998,$C4,clean!$E$2:$E$998,$D4,clean!$F$2:$F$998,$E4) -> 162000 | X4: =I4-T4-U4-V4-W4 -> 8.5536043e+08 | Y4: =AVERAGEIFS(clean!X$2:X$998,clean!$B$2:$B$998,$A4,clean!$C$2:$C$998,$B4,clean!$D$2:$D$998,$C4,clean!$E$2:$E$998,$D4,clean!$F$2:$F$998,$E4) -> 680044100
A5: 65536 | B5: 3 | C5: 64 | D5: 0.8 | E5: 10 | F5: =AVERAGEIFS(clean!G$2:G$998,clean!$B$2:$B$998,$A5,clean!$C$2:$C$998,$B5,clean!$D$2:$D$998,$C5,clean!$E$2:$E$998,$D5,clean!$F$2:$F$998,$E5) -> 2047 | G5: =AVERAGEIFS(clean!H$2:H$998,clean!$B$2:$B$998,$A5,clean!$C$2:$C$998,$B5,clean!$D$2:$D$998,$C5,clean!$E$2:$E$998,$D5,clean!$F$2:$F$998,$E5) -> 6825.3333 | H5: =AVERAGEIFS(clean!I$2:I$998,clean!$B$2:$B$998,$A5,clean!$C$2:$C$998,$B5,clean!$D$2:$D$998,$C5,clean!$E$2:$E$998,$D5,clean!$F$2:$F$998,$E5) -> 345786300 | I5: =AVERAGEIFS(clean!J$2:J$998,clean!$B$2:$B$998,$A5,clean!$C$2:$C$998,$B5,clean!$D$2:$D$998,$C5,clean!$E$2:$E$998,$D5,clean!$F$2:$F$998,$E5) -> 1.0853174e+09 | J5: =AVERAGEIFS(clean!K$2:K$998,clean!$B$2:$B$998,$A5,clean!$C$2:$C$998,$B5,clean!$D$2:$D$998,$C5,clean!$E$2:$E$998,$D5,clean!$F$2:$F$998,$E5) -> 3.1495345 | K5: =AVERAGEIFS(clean!L$2:L$998,clean!$B$2:$B$998,$A5,clean!$C$2:$C$998,$B5,clean!$D$2:$D$998,$C5,clean!$E$2:$E$998,$D5,clean!$F$2:$F$998,$E5) -> 1662566.7 | L5: =AVERAGEIFS(clean!M$2:M$998,clean!$B$2:$B$998,$A5,clean!$C$2:$C$998,$B5,clean!$D$2:$D$998,$C5,clean!$E$2:$E$998,$D5,clean!$F$2:$F$998,$E5) -> 1.5521353e+08 | M5: =AVERAGEIFS(clean!N$2:N$998,clean!$B$2:$B$998,$A5,clean!$C$2:$C$998,$B5,clean!$D$2:$D$998,$C5,clean!$E$2:$E$998,$D5,clean!$F$2:$F$998,$E5) -> 80790800 | ... R5: =AVERAGEIFS(clean!S$2:S$998,clean!$B$2:$B$998,$A5,clean!$C$2:$C$998,$B5,clean!$D$2:$D$998,$C5,clean!$E$2:$E$998,$D5,clean!$F$2:$F$998,$E5) -> 673866.67 | S5: =H5-K5-N5-Q5-R5 -> 32745167 | T5: =AVERAGEIFS(clean!T$2:T$998,clean!$B$2:$B$998,$A5,clean!$C$2:$C$998,$B5,clean!$D$2:$D$998,$C5,clean!$E$2:$E$998,$D5,clean!$F$2:$F$998,$E5) -> 17134400 | U5: =AVERAGEIFS(clean!U$2:U$998,clean!$B$2:$B$998,$A5,clean!$C$2:$C$998,$B5,clean!$D$2:$D$998,$C5,clean!$E$2:$E$998,$D5,clean!$F$2:$F$998,$E5) -> 3.3230827e+08 | V5: =AVERAGEIFS(clean!V$2:V$998,clean!$B$2:$B$998,$A5,clean!$C$2:$C$998,$B5,clean!$D$2:$D$998,$C5,clean!$E$2:$E$998,$D5,clean!$F$2:$F$998,$E5) -> 410796900 | W5: =AVERAGEIFS(clean!W$2:W$998,clean!$B$2:$B$998,$A5,clean!$C$2:$C$998,$B5,clean!$D$2:$D$998,$C5,clean!$E$2:$E$998,$D5,clean!$F$2:$F$998,$E5) -> 143700 | X5: =I5-T5-U5-V5-W5 -> 324934100 | Y5: =AVERAGEIFS(clean!X$2:X$998,clean!$B$2:$B$998,$A5,clean!$C$2:$C$998,$B5,clean!$D$2:$D$998,$C5,clean!$E$2:$E$998,$D5,clean!$F$2:$F$998,$E5) -> 345786300
A6: 65536 | B6: 4 | C6: 125 | D6: 0.65 | E6: 10 | F6: =AVERAGEIFS(clean!G$2:G$998,clean!$B$2:$B$998,$A6,clean!$C$2:$C$998,$B6,clean!$D$2:$D$998,$C6,clean!$E$2:$E$998,$D6,clean!$F$2:$F$998,$E6) -> 2047 | G6: =AVERAGEIFS(clean!H$2:H$998,clean!$B$2:$B$998,$A6,clean!$C$2:$C$998,$B6,clean!$D$2:$D$998,$C6,clean!$E$2:$E$998,$D6,clean!$F$2:$F$998,$E6) -> 11972 | H6: =AVERAGEIFS(clean!I$2:I$998,clean!$B$2:$B$998,$A6,clean!$C$2:$C$998,$B6,clean!$D$2:$D$998,$C6,clean!$E$2:$E$998,$D6,clean!$F$2:$F$998,$E6) -> 8.3684193e+08 | I6: =AVERAGEIFS(clean!J$2:J$998,clean!$B$2:$B$998,$A6,clean!$C$2:$C$998,$B6,clean!$D$2:$D$998,$C6,clean!$E$2:$E$998,$D6,clean!$F$2:$F$998,$E6) -> 3728202800 | J6: =AVERAGEIFS(clean!K$2:K$998,clean!$B$2:$B$998,$A6,clean!$C$2:$C$998,$B6,clean!$D$2:$D$998,$C6,clean!$E$2:$E$998,$D6,clean!$F$2:$F$998,$E6) -> 4.4545006 | K6: =AVERAGEIFS(clean!L$2:L$998,clean!$B$2:$B$998,$A6,clean!$C$2:$C$998,$B6,clean!$D$2:$D$998,$C6,clean!$E$2:$E$998,$D6,clean!$F$2:$F$998,$E6) -> 2810466.7 | L6: =AVERAGEIFS(clean!M$2:M$998,clean!$B$2:$B$998,$A6,clean!$C$2:$C$998,$B6,clean!$D$2:$D$998,$C6,clean!$E$2:$E$998,$D6,clean!$F$2:$F$998,$E6) -> 294072600 | M6: =AVERAGEIFS(clean!N$2:N$998,clean!$B$2:$B$998,$A6,clean!$C$2:$C$998,$B6,clean!$D$2:$D$998,$C6,clean!$E$2:$E$998,$D6,clean!$F$2:$F$998,$E6) -> 379075400 | ... R6: =AVERAGEIFS(clean!S$2:S$998,clean!$B$2:$B$998,$A6,clean!$C$2:$C$998,$B6,clean!$D$2:$D$998,$C6,clean!$E$2:$E$998,$D6,clean!$F$2:$F$998,$E6) -> 725500 | S6: =H6-K6-N6-Q6-R6 -> 54778233 | T6: =AVERAGEIFS(clean!T$2:T$998,clean!$B$2:$B$998,$A6,clean!$C$2:$C$998,$B6,clean!$D$2:$D$998,$C6,clean!$E$2:$E$998,$D6,clean!$F$2:$F$998,$E6) -> 25752567 | U6: =AVERAGEIFS(clean!U$2:U$998,clean!$B$2:$B$998,$A6,clean!$C$2:$C$998,$B6,clean!$D$2:$D$998,$C6,clean!$E$2:$E$998,$D6,clean!$F$2:$F$998,$E6) -> 2029296600 | V6: =AVERAGEIFS(clean!V$2:V$998,clean!$B$2:$B$998,$A6,clean!$C$2:$C$998,$B6,clean!$D$2:$D$998,$C6,clean!$E$2:$E$998,$D6,clean!$F$2:$F$998,$E6) -> 7.0884723e+08 | W6: =AVERAGEIFS(clean!W$2:W$998,clean!$B$2:$B$998,$A6,clean!$C$2:$C$998,$B6,clean!$D$2:$D$998,$C6,clean!$E$2:$E$998,$D6,clean!$F$2:$F$998,$E6) -> 144233.33 | X6: =I6-T6-U6-V6-W6 -> 9.6416217e+08 | Y6: =AVERAGEIFS(clean!X$2:X$998,clean!$B$2:$B$998,$A6,clean!$C$2:$C$998,$B6,clean!$D$2:$D$998,$C6,clean!$E$2:$E$998,$D6,clean!$F$2:$F$998,$E6) -> 8.3684193e+08
A7: 65536 | B7: 5 | C7: 216 | D7: 0.95 | E7: 9 | F7: =AVERAGEIFS(clean!G$2:G$998,clean!$B$2:$B$998,$A7,clean!$C$2:$C$998,$B7,clean!$D$2:$D$998,$C7,clean!$E$2:$E$998,$D7,clean!$F$2:$F$998,$E7) -> 1023 | G7: =AVERAGEIFS(clean!H$2:H$998,clean!$B$2:$B$998,$A7,clean!$C$2:$C$998,$B7,clean!$D$2:$D$998,$C7,clean!$E$2:$E$998,$D7,clean!$F$2:$F$998,$E7) -> 3072 | H7: =AVERAGEIFS(clean!I$2:I$998,clean!$B$2:$B$998,$A7,clean!$C$2:$C$998,$B7,clean!$D$2:$D$998,$C7,clean!$E$2:$E$998,$D7,clean!$F$2:$F$998,$E7) -> 848923800 | I7: =AVERAGEIFS(clean!J$2:J$998,clean!$B$2:$B$998,$A7,clean!$C$2:$C$998,$B7,clean!$D$2:$D$998,$C7,clean!$E$2:$E$998,$D7,clean!$F$2:$F$998,$E7) -> 2.3729893e+09 | J7: =AVERAGEIFS(clean!K$2:K$998,clean!$B$2:$B$998,$A7,clean!$C$2:$C$998,$B7,clean!$D$2:$D$998,$C7,clean!$E$2:$E$998,$D7,clean!$F$2:$F$998,$E7) -> 2.7936754 | K7: =AVERAGEIFS(clean!L$2:L$998,clean!$B$2:$B$998,$A7,clean!$C$2:$C$998,$B7,clean!$D$2:$D$998,$C7,clean!$E$2:$E$998,$D7,clean!$F$2:$F$998,$E7) -> 478233.33 | L7: =AVERAGEIFS(clean!M$2:M$998,clean!$B$2:$B$998,$A7,clean!$C$2:$C$998,$B7,clean!$D$2:$D$998,$C7,clean!$E$2:$E$998,$D7,clean!$F$2:$F$998,$E7) -> 5.6874837e+08 | M7: =AVERAGEIFS(clean!N$2:N$998,clean!$B$2:$B$998,$A7,clean!$C$2:$C$998,$B7,clean!$D$2:$D$998,$C7,clean!$E$2:$E$998,$D7,clean!$F$2:$F$998,$E7) -> 98950433 | ... R7: =AVERAGEIFS(clean!S$2:S$998,clean!$B$2:$B$998,$A7,clean!$C$2:$C$998,$B7,clean!$D$2:$D$998,$C7,clean!$E$2:$E$998,$D7,clean!$F$2:$F$998,$E7) -> 708000 | S7: =H7-K7-N7-Q7-R7 -> 73357767 | T7: =AVERAGEIFS(clean!T$2:T$998,clean!$B$2:$B$998,$A7,clean!$C$2:$C$998,$B7,clean!$D$2:$D$998,$C7,clean!$E$2:$E$998,$D7,clean!$F$2:$F$998,$E7) -> 22946067 | U7: =AVERAGEIFS(clean!U$2:U$998,clean!$B$2:$B$998,$A7,clean!$C$2:$C$998,$B7,clean!$D$2:$D$998,$C7,clean!$E$2:$E$998,$D7,clean!$F$2:$F$998,$E7) -> 5.5048817e+08 | V7: =AVERAGEIFS(clean!V$2:V$998,clean!$B$2:$B$998,$A7,clean!$C$2:$C$998,$B7,clean!$D$2:$D$998,$C7,clean!$E$2:$E$998,$D7,clean!$F$2:$F$998,$E7) -> 7.4717627e+08 | W7: =AVERAGEIFS(clean!W$2:W$998,clean!$B$2:$B$998,$A7,clean!$C$2:$C$998,$B7,clean!$D$2:$D$998,$C7,clean!$E$2:$E$998,$D7,clean!$F$2:$F$998,$E7) -> 145000 | X7: =I7-T7-U7-V7-W7 -> 1.0522338e+09 | Y7: =AVERAGEIFS(clean!X$2:X$998,clean!$B$2:$B$998,$A7,clean!$C$2:$C$998,$B7,clean!$D$2:$D$998,$C7,clean!$E$2:$E$998,$D7,clean!$F$2:$F$998,$E7) -> 848923800
A8: 65536 | B8: 3 | C8: 64 | D8: 0.65 | E8: 10 | F8: =AVERAGEIFS(clean!G$2:G$998,clean!$B$2:$B$998,$A8,clean!$C$2:$C$998,$B8,clean!$D$2:$D$998,$C8,clean!$E$2:$E$998,$D8,clean!$F$2:$F$998,$E8) -> 2047 | G8: =AVERAGEIFS(clean!H$2:H$998,clean!$B$2:$B$998,$A8,clean!$C$2:$C$998,$B8,clean!$D$2:$D$998,$C8,clean!$E$2:$E$998,$D8,clean!$F$2:$F$998,$E8) -> 11989.333 | H8: =AVERAGEIFS(clean!I$2:I$998,clean!$B$2:$B$998,$A8,clean!$C$2:$C$998,$B8,clean!$D$2:$D$998,$C8,clean!$E$2:$E$998,$D8,clean!$F$2:$F$998,$E8) -> 4.8173507e+08 | I8: =AVERAGEIFS(clean!J$2:J$998,clean!$B$2:$B$998,$A8,clean!$C$2:$C$998,$B8,clean!$D$2:$D$998,$C8,clean!$E$2:$E$998,$D8,clean!$F$2:$F$998,$E8) -> 1722379700 | J8: =AVERAGEIFS(clean!K$2:K$998,clean!$B$2:$B$998,$A8,clean!$C$2:$C$998,$B8,clean!$D$2:$D$998,$C8,clean!$E$2:$E$998,$D8,clean!$F$2:$F$998,$E8) -> 3.5922599 | K8: =AVERAGEIFS(clean!L$2:L$998,clean!$B$2:$B$998,$A8,clean!$C$2:$C$998,$B8,clean!$D$2:$D$998,$C8,clean!$E$2:$E$998,$D8,clean!$F$2:$F$998,$E8) -> 2737766.7 | L8: =AVERAGEIFS(clean!M$2:M$998,clean!$B$2:$B$998,$A8,clean!$C$2:$C$998,$B8,clean!$D$2:$D$998,$C8,clean!$E$2:$E$998,$D8,clean!$F$2:$F$998,$E8) -> 186709100 | M8: =AVERAGEIFS(clean!N$2:N$998,clean!$B$2:$B$998,$A8,clean!$C$2:$C$998,$B8,clean!$D$2:$D$998,$C8,clean!$E$2:$E$998,$D8,clean!$F$2:$F$998,$E8) -> 136306800 | ... R8: =AVERAGEIFS(clean!S$2:S$998,clean!$B$2:$B$998,$A8,clean!$C$2:$C$998,$B8,clean!$D$2:$D$998,$C8,clean!$E$2:$E$998,$D8,clean!$F$2:$F$998,$E8) -> 719066.67 | S8: =H8-K8-N8-Q8-R8 -> 32900000 | T8: =AVERAGEIFS(clean!T$2:T$998,clean!$B$2:$B$998,$A8,clean!$C$2:$C$998,$B8,clean!$D$2:$D$998,$C8,clean!$E$2:$E$998,$D8,clean!$F$2:$F$998,$E8) -> 19275267 | U8: =AVERAGEIFS(clean!U$2:U$998,clean!$B$2:$B$998,$A8,clean!$C$2:$C$998,$B8,clean!$D$2:$D$998,$C8,clean!$E$2:$E$998,$D8,clean!$F$2:$F$998,$E8) -> 5.5397647e+08 | V8: =AVERAGEIFS(clean!V$2:V$998,clean!$B$2:$B$998,$A8,clean!$C$2:$C$998,$B8,clean!$D$2:$D$998,$C8,clean!$E$2:$E$998,$D8,clean!$F$2:$F$998,$E8) -> 7.1830887e+08 | W8: =AVERAGEIFS(clean!W$2:W$998,clean!$B$2:$B$998,$A8,clean!$C$2:$C$998,$B8,clean!$D$2:$D$998,$C8,clean!$E$2:$E$998,$D8,clean!$F$2:$F$998,$E8) -> 148700 | X8: =I8-T8-U8-V8-W8 -> 4.306704e+08 | Y8: =AVERAGEIFS(clean!X$2:X$998,clean!$B$2:$B$998,$A8,clean!$C$2:$C$998,$B8,clean!$D$2:$D$998,$C8,clean!$E$2:$E$998,$D8,clean!$F$2:$F$998,$E8) -> 4.8173507e+08
A9: 65536 | B9: 7 | C9: 512 | D9: 0.95 | E9: 7 | F9: =AVERAGEIFS(clean!G$2:G$998,clean!$B$2:$B$998,$A9,clean!$C$2:$C$998,$B9,clean!$D$2:$D$998,$C9,clean!$E$2:$E$998,$D9,clean!$F$2:$F$998,$E9) -> 255 | G9: =AVERAGEIFS(clean!H$2:H$998,clean!$B$2:$B$998,$A9,clean!$C$2:$C$998,$B9,clean!$D$2:$D$998,$C9,clean!$E$2:$E$998,$D9,clean!$F$2:$F$998,$E9) -> 256 | H9: =AVERAGEIFS(clean!I$2:I$998,clean!$B$2:$B$998,$A9,clean!$C$2:$C$998,$B9,clean!$D$2:$D$998,$C9,clean!$E$2:$E$998,$D9,clean!$F$2:$F$998,$E9) -> 1808769300 | I9: =AVERAGEIFS(clean!J$2:J$998,clean!$B$2:$B$998,$A9,clean!$C$2:$C$998,$B9,clean!$D$2:$D$998,$C9,clean!$E$2:$E$998,$D9,clean!$F$2:$F$998,$E9) -> 4207049400 | J9: =AVERAGEIFS(clean!K$2:K$998,clean!$B$2:$B$998,$A9,clean!$C$2:$C$998,$B9,clean!$D$2:$D$998,$C9,clean!$E$2:$E$998,$D9,clean!$F$2:$F$998,$E9) -> 2.3290064 | K9: =AVERAGEIFS(clean!L$2:L$998,clean!$B$2:$B$998,$A9,clean!$C$2:$C$998,$B9,clean!$D$2:$D$998,$C9,clean!$E$2:$E$998,$D9,clean!$F$2:$F$998,$E9) -> 100533.33 | L9: =AVERAGEIFS(clean!M$2:M$998,clean!$B$2:$B$998,$A9,clean!$C$2:$C$998,$B9,clean!$D$2:$D$998,$C9,clean!$E$2:$E$998,$D9,clean!$F$2:$F$998,$E9) -> 1.2873876e+09 | M9: =AVERAGEIFS(clean!N$2:N$998,clean!$B$2:$B$998,$A9,clean!$C$2:$C$998,$B9,clean!$D$2:$D$998,$C9,clean!$E$2:$E$998,$D9,clean!$F$2:$F$998,$E9) -> 2.8336463e+08 | ... R9: =AVERAGEIFS(clean!S$2:S$998,clean!$B$2:$B$998,$A9,clean!$C$2:$C$998,$B9,clean!$D$2:$D$998,$C9,clean!$E$2:$E$998,$D9,clean!$F$2:$F$998,$E9) -> 718433.33 | S9: =H9-K9-N9-Q9-R9 -> 95691333 | T9: =AVERAGEIFS(clean!T$2:T$998,clean!$B$2:$B$998,$A9,clean!$C$2:$C$998,$B9,clean!$D$2:$D$998,$C9,clean!$E$2:$E$998,$D9,clean!$F$2:$F$998,$E9) -> 11403900 | U9: =AVERAGEIFS(clean!U$2:U$998,clean!$B$2:$B$998,$A9,clean!$C$2:$C$998,$B9,clean!$D$2:$D$998,$C9,clean!$E$2:$E$998,$D9,clean!$F$2:$F$998,$E9) -> 1521014100 | V9: =AVERAGEIFS(clean!V$2:V$998,clean!$B$2:$B$998,$A9,clean!$C$2:$C$998,$B9,clean!$D$2:$D$998,$C9,clean!$E$2:$E$998,$D9,clean!$F$2:$F$998,$E9) -> 1.1055007e+09 | W9: =AVERAGEIFS(clean!W$2:W$998,clean!$B$2:$B$998,$A9,clean!$C$2:$C$998,$B9,clean!$D$2:$D$998,$C9,clean!$E$2:$E$998,$D9,clean!$F$2:$F$998,$E9) -> 190233.33 | X9: =I9-T9-U9-V9-W9 -> 1.5689404e+09 | Y9: =AVERAGEIFS(clean!X$2:X$998,clean!$B$2:$B$998,$A9,clean!$C$2:$C$998,$B9,clean!$D$2:$D$998,$C9,clean!$E$2:$E$998,$D9,clean!$F$2:$F$998,$E9) -> 1808769300
A10: 65536 | B10: 6 | C10: 343 | D10: 0.95 | E10: 8 | F10: =AVERAGEIFS(clean!G$2:G$998,clean!$B$2:$B$998,$A10,clean!$C$2:$C$998,$B10,clean!$D$2:$D$998,$C10,clean!$E$2:$E$998,$D10,clean!$F$2:$F$998,$E10) -> 511 | G10: =AVERAGEIFS(clean!H$2:H$998,clean!$B$2:$B$998,$A10,clean!$C$2:$C$998,$B10,clean!$D$2:$D$998,$C10,clean!$E$2:$E$998,$D10,clean!$F$2:$F$998,$E10) -> 1024 | H10: =AVERAGEIFS(clean!I$2:I$998,clean!$B$2:$B$998,$A10,clean!$C$2:$C$998,$B10,clean!$D$2:$D$998,$C10,clean!$E$2:$E$998,$D10,clean!$F$2:$F$998,$E10) -> 1.4626073e+09 | I10: =AVERAGEIFS(clean!J$2:J$998,clean!$B$2:$B$998,$A10,clean!$C$2:$C$998,$B10,clean!$D$2:$D$998,$C10,clean!$E$2:$E$998,$D10,clean!$F$2:$F$998,$E10) -> 3.0635774e+09 | J10: =AVERAGEIFS(clean!K$2:K$998,clean!$B$2:$B$998,$A10,clean!$C$2:$C$998,$B10,clean!$D$2:$D$998,$C10,clean!$E$2:$E$998,$D10,clean!$F$2:$F$998,$E10) -> 2.095951 | K10: =AVERAGEIFS(clean!L$2:L$998,clean!$B$2:$B$998,$A10,clean!$C$2:$C$998,$B10,clean!$D$2:$D$998,$C10,clean!$E$2:$E$998,$D10,clean!$F$2:$F$998,$E10) -> 203433.33 | L10: =AVERAGEIFS(clean!M$2:M$998,clean!$B$2:$B$998,$A10,clean!$C$2:$C$998,$B10,clean!$D$2:$D$998,$C10,clean!$E$2:$E$998,$D10,clean!$F$2:$F$998,$E10) -> 1.0821039e+09 | M10: =AVERAGEIFS(clean!N$2:N$998,clean!$B$2:$B$998,$A10,clean!$C$2:$C$998,$B10,clean!$D$2:$D$998,$C10,clean!$E$2:$E$998,$D10,clean!$F$2:$F$998,$E10) -> 143161800 | ... R10: =AVERAGEIFS(clean!S$2:S$998,clean!$B$2:$B$998,$A10,clean!$C$2:$C$998,$B10,clean!$D$2:$D$998,$C10,clean!$E$2:$E$998,$D10,clean!$F$2:$F$998,$E10) -> 684833.33 | S10: =H10-K10-N10-Q10-R10 -> 94791900 | T10: =AVERAGEIFS(clean!T$2:T$998,clean!$B$2:$B$998,$A10,clean!$C$2:$C$998,$B10,clean!$D$2:$D$998,$C10,clean!$E$2:$E$998,$D10,clean!$F$2:$F$998,$E10) -> 20062233 | U10: =AVERAGEIFS(clean!U$2:U$998,clean!$B$2:$B$998,$A10,clean!$C$2:$C$998,$B10,clean!$D$2:$D$998,$C10,clean!$E$2:$E$998,$D10,clean!$F$2:$F$998,$E10) -> 669008100 | V10: =AVERAGEIFS(clean!V$2:V$998,clean!$B$2:$B$998,$A10,clean!$C$2:$C$998,$B10,clean!$D$2:$D$998,$C10,clean!$E$2:$E$998,$D10,clean!$F$2:$F$998,$E10) -> 1.0547141e+09 | W10: =AVERAGEIFS(clean!W$2:W$998,clean!$B$2:$B$998,$A10,clean!$C$2:$C$998,$B10,clean!$D$2:$D$998,$C10,clean!$E$2:$E$998,$D10,clean!$F$2:$F$998,$E10) -> 190500 | X10: =I10-T10-U10-V10-W10 -> 1.3196024e+09 | Y10: =AVERAGEIFS(clean!X$2:X$998,clean!$B$2:$B$998,$A10,clean!$C$2:$C$998,$B10,clean!$D$2:$D$998,$C10,clean!$E$2:$E$998,$D10,clean!$F$2:$F$998,$E10) -> 1.4626073e+09
A11: 65536 | B11: 5 | C11: 216 | D11: 0.8 | E11: 9 | F11: =AVERAGEIFS(clean!G$2:G$998,clean!$B$2:$B$998,$A11,clean!$C$2:$C$998,$B11,clean!$D$2:$D$998,$C11,clean!$E$2:$E$998,$D11,clean!$F$2:$F$998,$E11) -> 1023 | G11: =AVERAGEIFS(clean!H$2:H$998,clean!$B$2:$B$998,$A11,clean!$C$2:$C$998,$B11,clean!$D$2:$D$998,$C11,clean!$E$2:$E$998,$D11,clean!$F$2:$F$998,$E11) -> 4174.6667 | H11: =AVERAGEIFS(clean!I$2:I$998,clean!$B$2:$B$998,$A11,clean!$C$2:$C$998,$B11,clean!$D$2:$D$998,$C11,clean!$E$2:$E$998,$D11,clean!$F$2:$F$998,$E11) -> 1.1147482e+09 | I11: =AVERAGEIFS(clean!J$2:J$998,clean!$B$2:$B$998,$A11,clean!$C$2:$C$998,$B11,clean!$D$2:$D$998,$C11,clean!$E$2:$E$998,$D11,clean!$F$2:$F$998,$E11) -> 3.6872405e+09 | J11: =AVERAGEIFS(clean!K$2:K$998,clean!$B$2:$B$998,$A11,clean!$C$2:$C$998,$B11,clean!$D$2:$D$998,$C11,clean!$E$2:$E$998,$D11,clean!$F$2:$F$998,$E11) -> 3.3066696 | K11: =AVERAGEIFS(clean!L$2:L$998,clean!$B$2:$B$998,$A11,clean!$C$2:$C$998,$B11,clean!$D$2:$D$998,$C11,clean!$E$2:$E$998,$D11,clean!$F$2:$F$998,$E11) -> 950900 | L11: =AVERAGEIFS(clean!M$2:M$998,clean!$B$2:$B$998,$A11,clean!$C$2:$C$998,$B11,clean!$D$2:$D$998,$C11,clean!$E$2:$E$998,$D11,clean!$F$2:$F$998,$E11) -> 5.8366317e+08 | M11: =AVERAGEIFS(clean!N$2:N$998,clean!$B$2:$B$998,$A11,clean!$C$2:$C$998,$B11,clean!$D$2:$D$998,$C11,clean!$E$2:$E$998,$D11,clean!$F$2:$F$998,$E11) -> 3.1427653e+08 | ... R11: =AVERAGEIFS(clean!S$2:S$998,clean!$B$2:$B$998,$A11,clean!$C$2:$C$998,$B11,clean!$D$2:$D$998,$C11,clean!$E$2:$E$998,$D11,clean!$F$2:$F$998,$E11) -> 793033.33 | S11: =H11-K11-N11-Q11-R11 -> 72543633 | T11: =AVERAGEIFS(clean!T$2:T$998,clean!$B$2:$B$998,$A11,clean!$C$2:$C$998,$B11,clean!$D$2:$D$998,$C11,clean!$E$2:$E$998,$D11,clean!$F$2:$F$998,$E11) -> 21735300 | U11: =AVERAGEIFS(clean!U$2:U$998,clean!$B$2:$B$998,$A11,clean!$C$2:$C$998,$B11,clean!$D$2:$D$998,$C11,clean!$E$2:$E$998,$D11,clean!$F$2:$F$998,$E11) -> 1489700700 | V11: =AVERAGEIFS(clean!V$2:V$998,clean!$B$2:$B$998,$A11,clean!$C$2:$C$998,$B11,clean!$D$2:$D$998,$C11,clean!$E$2:$E$998,$D11,clean!$F$2:$F$998,$E11) -> 1029280300 | W11: =AVERAGEIFS(clean!W$2:W$998,clean!$B$2:$B$998,$A11,clean!$C$2:$C$998,$B11,clean!$D$2:$D$998,$C11,clean!$E$2:$E$998,$D11,clean!$F$2:$F$998,$E11) -> 165133.33 | X11: =I11-T11-U11-V11-W11 -> 1.146359e+09 | Y11: =AVERAGEIFS(clean!X$2:X$998,clean!$B$2:$B$998,$A11,clean!$C$2:$C$998,$B11,clean!$D$2:$D$998,$C11,clean!$E$2:$E$998,$D11,clean!$F$2:$F$998,$E11) -> 1.1147482e+09
A12: 65536 | B12: 6 | C12: 343 | D12: 0.8 | E12: 8 | F12: =AVERAGEIFS(clean!G$2:G$998,clean!$B$2:$B$998,$A12,clean!$C$2:$C$998,$B12,clean!$D$2:$D$998,$C12,clean!$E$2:$E$998,$D12,clean!$F$2:$F$998,$E12) -> 511 | G12: =AVERAGEIFS(clean!H$2:H$998,clean!$B$2:$B$998,$A12,clean!$C$2:$C$998,$B12,clean!$D$2:$D$998,$C12,clean!$E$2:$E$998,$D12,clean!$F$2:$F$998,$E12) -> 1869.3333 | H12: =AVERAGEIFS(clean!I$2:I$998,clean!$B$2:$B$998,$A12,clean!$C$2:$C$998,$B12,clean!$D$2:$D$998,$C12,clean!$E$2:$E$998,$D12,clean!$F$2:$F$998,$E12) -> 1.8123098e+09 | I12: =AVERAGEIFS(clean!J$2:J$998,clean!$B$2:$B$998,$A12,clean!$C$2:$C$998,$B12,clean!$D$2:$D$998,$C12,clean!$E$2:$E$998,$D12,clean!$F$2:$F$998,$E12) -> 5.2018297e+09 | J12: =AVERAGEIFS(clean!K$2:K$998,clean!$B$2:$B$998,$A12,clean!$C$2:$C$998,$B12,clean!$D$2:$D$998,$C12,clean!$E$2:$E$998,$D12,clean!$F$2:$F$998,$E12) -> 2.8746031 | K12: =AVERAGEIFS(clean!L$2:L$998,clean!$B$2:$B$998,$A12,clean!$C$2:$C$998,$B12,clean!$D$2:$D$998,$C12,clean!$E$2:$E$998,$D12,clean!$F$2:$F$998,$E12) -> 395466.67 | L12: =AVERAGEIFS(clean!M$2:M$998,clean!$B$2:$B$998,$A12,clean!$C$2:$C$998,$B12,clean!$D$2:$D$998,$C12,clean!$E$2:$E$998,$D12,clean!$F$2:$F$998,$E12) -> 1.0861844e+09 | M12: =AVERAGEIFS(clean!N$2:N$998,clean!$B$2:$B$998,$A12,clean!$C$2:$C$998,$B12,clean!$D$2:$D$998,$C12,clean!$E$2:$E$998,$D12,clean!$F$2:$F$998,$E12) -> 3.7594453e+08 | ... R12: =AVERAGEIFS(clean!S$2:S$998,clean!$B$2:$B$998,$A12,clean!$C$2:$C$998,$B12,clean!$D$2:$D$998,$C12,clean!$E$2:$E$998,$D12,clean!$F$2:$F$998,$E12) -> 720600 | S12: =H12-K12-N12-Q12-R12 -> 94196600 | T12: =AVERAGEIFS(clean!T$2:T$998,clean!$B$2:$B$998,$A12,clean!$C$2:$C$998,$B12,clean!$D$2:$D$998,$C12,clean!$E$2:$E$998,$D12,clean!$F$2:$F$998,$E12) -> 18052433 | U12: =AVERAGEIFS(clean!U$2:U$998,clean!$B$2:$B$998,$A12,clean!$C$2:$C$998,$B12,clean!$D$2:$D$998,$C12,clean!$E$2:$E$998,$D12,clean!$F$2:$F$998,$E12) -> 1.7716255e+09 | V12: =AVERAGEIFS(clean!V$2:V$998,clean!$B$2:$B$998,$A12,clean!$C$2:$C$998,$B12,clean!$D$2:$D$998,$C12,clean!$E$2:$E$998,$D12,clean!$F$2:$F$998,$E12) -> 1909187500 | W12: =AVERAGEIFS(clean!W$2:W$998,clean!$B$2:$B$998,$A12,clean!$C$2:$C$998,$B12,clean!$D$2:$D$998,$C12,clean!$E$2:$E$998,$D12,clean!$F$2:$F$998,$E12) -> 151800 | X12: =I12-T12-U12-V12-W12 -> 1.5028125e+09 | Y12: =AVERAGEIFS(clean!X$2:X$998,clean!$B$2:$B$998,$A12,clean!$C$2:$C$998,$B12,clean!$D$2:$D$998,$C12,clean!$E$2:$E$998,$D12,clean!$F$2:$F$998,$E12) -> 1.8123098e+09
A13: 65536 | B13: 5 | C13: 216 | D13: 0.65 | E13: 9 | F13: =AVERAGEIFS(clean!G$2:G$998,clean!$B$2:$B$998,$A13,clean!$C$2:$C$998,$B13,clean!$D$2:$D$998,$C13,clean!$E$2:$E$998,$D13,clean!$F$2:$F$998,$E13) -> 1023 | G13: =AVERAGEIFS(clean!H$2:H$998,clean!$B$2:$B$998,$A13,clean!$C$2:$C$998,$B13,clean!$D$2:$D$998,$C13,clean!$E$2:$E$998,$D13,clean!$F$2:$F$998,$E13) -> 8340 | H13: =AVERAGEIFS(clean!I$2:I$998,clean!$B$2:$B$998,$A13,clean!$C$2:$C$998,$B13,clean!$D$2:$D$998,$C13,clean!$E$2:$E$998,$D13,clean!$F$2:$F$998,$E13) -> 1.9037465e+09 | I13: =AVERAGEIFS(clean!J$2:J$998,clean!$B$2:$B$998,$A13,clean!$C$2:$C$998,$B13,clean!$D$2:$D$998,$C13,clean!$E$2:$E$998,$D13,clean!$F$2:$F$998,$E13) -> 5.4704292e+09 | J13: =AVERAGEIFS(clean!K$2:K$998,clean!$B$2:$B$998,$A13,clean!$C$2:$C$998,$B13,clean!$D$2:$D$998,$C13,clean!$E$2:$E$998,$D13,clean!$F$2:$F$998,$E13) -> 2.8761545 | K13: =AVERAGEIFS(clean!L$2:L$998,clean!$B$2:$B$998,$A13,clean!$C$2:$C$998,$B13,clean!$D$2:$D$998,$C13,clean!$E$2:$E$998,$D13,clean!$F$2:$F$998,$E13) -> 1422300 | L13: =AVERAGEIFS(clean!M$2:M$998,clean!$B$2:$B$998,$A13,clean!$C$2:$C$998,$B13,clean!$D$2:$D$998,$C13,clean!$E$2:$E$998,$D13,clean!$F$2:$F$998,$E13) -> 5.1301963e+08 | M13: =AVERAGEIFS(clean!N$2:N$998,clean!$B$2:$B$998,$A13,clean!$C$2:$C$998,$B13,clean!$D$2:$D$998,$C13,clean!$E$2:$E$998,$D13,clean!$F$2:$F$998,$E13) -> 4.6654837e+08 | ... R13: =AVERAGEIFS(clean!S$2:S$998,clean!$B$2:$B$998,$A13,clean!$C$2:$C$998,$B13,clean!$D$2:$D$998,$C13,clean!$E$2:$E$998,$D13,clean!$F$2:$F$998,$E13) -> 689300 | S13: =H13-K13-N13-Q13-R13 -> 6.4117223e+08 | T13: =AVERAGEIFS(clean!T$2:T$998,clean!$B$2:$B$998,$A13,clean!$C$2:$C$998,$B13,clean!$D$2:$D$998,$C13,clean!$E$2:$E$998,$D13,clean!$F$2:$F$998,$E13) -> 18435000 | U13: =AVERAGEIFS(clean!U$2:U$998,clean!$B$2:$B$998,$A13,clean!$C$2:$C$998,$B13,clean!$D$2:$D$998,$C13,clean!$E$2:$E$998,$D13,clean!$F$2:$F$998,$E13) -> 2232373400 | V13: =AVERAGEIFS(clean!V$2:V$998,clean!$B$2:$B$998,$A13,clean!$C$2:$C$998,$B13,clean!$D$2:$D$998,$C13,clean!$E$2:$E$998,$D13,clean!$F$2:$F$998,$E13) -> 2065882300 | W13: =AVERAGEIFS(clean!W$2:W$998,clean!$B$2:$B$998,$A13,clean!$C$2:$C$998,$B13,clean!$D$2:$D$998,$C13,clean!$E$2:$E$998,$D13,clean!$F$2:$F$998,$E13) -> 161700 | X13: =I13-T13-U13-V13-W13 -> 1.1535768e+09 | Y13: =AVERAGEIFS(clean!X$2:X$998,clean!$B$2:$B$998,$A13,clean!$C$2:$C$998,$B13,clean!$D$2:$D$998,$C13,clean!$E$2:$E$998,$D13,clean!$F$2:$F$998,$E13) -> 1.9037465e+09
... A151: 1048576 | B151: 7 | C151: 512 | D151: 0.2 | E151: 11 | F151: =AVERAGEIFS(clean!G$2:G$998,clean!$B$2:$B$998,$A151,clean!$C$2:$C$998,$B151,clean!$D$2:$D$998,$C151,clean!$E$2:$E$998,$D151,clean!$F$2:$F$998,$E151) -> 4095 | G151: =AVERAGEIFS(clean!H$2:H$998,clean!$B$2:$B$998,$A151,clean!$C$2:$C$998,$B151,clean!$D$2:$D$998,$C151,clean!$E$2:$E$998,$D151,clean!$F$2:$F$998,$E151) -> 958536 | H151: =AVERAGEIFS(clean!I$2:I$998,clean!$B$2:$B$998,$A151,clean!$C$2:$C$998,$B151,clean!$D$2:$D$998,$C151,clean!$E$2:$E$998,$D151,clean!$F$2:$F$998,$E151) -> 689438423400 | I151: =AVERAGEIFS(clean!J$2:J$998,clean!$B$2:$B$998,$A151,clean!$C$2:$C$998,$B151,clean!$D$2:$D$998,$C151,clean!$E$2:$E$998,$D151,clean!$F$2:$F$998,$E151) -> 5046620688500 | J151: =AVERAGEIFS(clean!K$2:K$998,clean!$B$2:$B$998,$A151,clean!$C$2:$C$998,$B151,clean!$D$2:$D$998,$C151,clean!$E$2:$E$998,$D151,clean!$F$2:$F$998,$E151) -> 7.319883 | K151: =AVERAGEIFS(clean!L$2:L$998,clean!$B$2:$B$998,$A151,clean!$C$2:$C$998,$B151,clean!$D$2:$D$998,$C151,clean!$E$2:$E$998,$D151,clean!$F$2:$F$998,$E151) -> 141157100 | L151: =AVERAGEIFS(clean!M$2:M$998,clean!$B$2:$B$998,$A151,clean!$C$2:$C$998,$B151,clean!$D$2:$D$998,$C151,clean!$E$2:$E$998,$D151,clean!$F$2:$F$998,$E151) -> 1.6558189e+10 | M151: =AVERAGEIFS(clean!N$2:N$998,clean!$B$2:$B$998,$A151,clean!$C$2:$C$998,$B151,clean!$D$2:$D$998,$C151,clean!$E$2:$E$998,$D151,clean!$F$2:$F$998,$E151) -> 1.5162429e+11 | ... R151: =AVERAGEIFS(clean!S$2:S$998,clean!$B$2:$B$998,$A151,clean!$C$2:$C$998,$B151,clean!$D$2:$D$998,$C151,clean!$E$2:$E$998,$D151,clean!$F$2:$F$998,$E151) -> 18094367 | S151: =H151-K151-N151-Q151-R151 -> 1.9851821e+09 | T151: =AVERAGEIFS(clean!T$2:T$998,clean!$B$2:$B$998,$A151,clean!$C$2:$C$998,$B151,clean!$D$2:$D$998,$C151,clean!$E$2:$E$998,$D151,clean!$F$2:$F$998,$E151) -> 7.6447873e+08 | U151: =AVERAGEIFS(clean!U$2:U$998,clean!$B$2:$B$998,$A151,clean!$C$2:$C$998,$B151,clean!$D$2:$D$998,$C151,clean!$E$2:$E$998,$D151,clean!$F$2:$F$998,$E151) -> 8.0459622e+11 | V151: =AVERAGEIFS(clean!V$2:V$998,clean!$B$2:$B$998,$A151,clean!$C$2:$C$998,$B151,clean!$D$2:$D$998,$C151,clean!$E$2:$E$998,$D151,clean!$F$2:$F$998,$E151) -> 4216013898300 | W151: =AVERAGEIFS(clean!W$2:W$998,clean!$B$2:$B$998,$A151,clean!$C$2:$C$998,$B151,clean!$D$2:$D$998,$C151,clean!$E$2:$E$998,$D151,clean!$F$2:$F$998,$E151) -> 3848600 | X151: =I151-T151-U151-V151-W151 -> 2.524224e+10 | Y151: =AVERAGEIFS(clean!X$2:X$998,clean!$B$2:$B$998,$A151,clean!$C$2:$C$998,$B151,clean!$D$2:$D$998,$C151,clean!$E$2:$E$998,$D151,clean!$F$2:$F$998,$E151) -> 689438423400

Sheet X
A1: N | B1: n | C1: N0 | D1: eta | E1: max_level | F1: num_clus | G1: min_nei | H1: t | I1: gpu_time | J1: cpu_time | K1: X total | L1: X M2L | M1: X P2P | N1: X update | O1: X collect | P1: X others FF | Q1: share GPU collect | R1: share GPU FF | S1: share GPU M2l | T1: share GPU NF | U1: share GPU update | V1: share CPU collect | W1: share CPU FF | X1: share CPU M2L | Y1: share CPU NF | Z1: share CPU update | AA1: share CPU others FF | AB1: ratio sahre NF/FF
A2: 524288 | B2: 4 | C2: 125 | D2: 0.95 | E2: 13 | F2: 16383 | G2: 16400 | H2: =A2/F2 -> 32.001953 | I2: 3.5023082e+09 | J2: 13498594600 | K2: =avg!I93/avg!H93 -> 3.8541996 | L2: =avg!U93/avg!N93 -> 2.2907904 | M2: =avg!V93/avg!Q93 -> 6.6018726 | N2: =avg!W93/avg!R93 -> 0.44616118 | O2: =avg!T93/avg!K93 -> 47.334086 | P2: =avg!X2/avg!S2 -> 13.304144 | Q2: =avg!K93/avg!H93 -> 0.0015041795 | R2: =1-Q2-T2-U2 -> 0.95331262 | S2: =avg!N93/avg!H93 -> 0.73033906 | T2: =avg!Q93/avg!H93 -> 0.044006036 | U2: =avg!R93/avg!H93 -> 0.0011771665 | V2: =avg!T93/avg!I93 -> 0.018473086 | W2: =1-V2-Y2-Z2 -> 0.90601254 | X2: =avg!U93/avg!I93 -> 0.43408591 | Y2: =avg!V93/avg!I93 -> 0.075378101 | Z2: =avg!W93/avg!I93 -> 0.00013626851 | AA2: =W2-X2 -> 0.47192663 | AB2: =Y2/W2 -> 0.083197636
A3: 65536 | B3: 4 | C3: 125 | D3: 0.95 | E3: 10 | F3: 2047 | G3: 2052 | H3: =A3/F3 -> 32.015633 | I3: 5.5375593e+08 | J3: 1.6449164e+09 | K3: =avg!I2/avg!H2 -> 2.9704719 | L3: =avg!U2/avg!N2 -> 1.5619457 | M3: =avg!V2/avg!Q2 -> 6.0013575 | N3: =avg!W2/avg!R2 -> 0.21230482 | O3: =avg!T2/avg!K2 -> 30.827992 | P3: =avg!X3/avg!S3 -> 13.502566 | Q3: =avg!K2/avg!H2 -> 0.0014124153 | R3: =1-Q3-T3-U3 -> 0.95845119 | S3: =avg!N2/avg!H2 -> 0.85655504 | T3: =avg!Q2/avg!H2 -> 0.038844911 | U3: =avg!R2/avg!H2 -> 0.0012914835 | V3: =avg!T2/avg!I2 -> 0.014658252 | W3: =1-V3-Y3-Z3 -> 0.90676959 | X3: =avg!U2/avg!I2 -> 0.45039727 | Y3: =avg!V2/avg!I2 -> 0.078479853 | Z3: =avg!W2/avg!I2 -> 9.2304588e-05 | AA3: =W3-X3 -> 0.45637232 | AB3: =Y3/W3 -> 0.086548837
A4: 131072 | B4: 5 | C4: 216 | D4: 0.95 | E4: 10 | F4: 2047 | G4: 2048 | H4: =A4/F4 -> 64.031265 | I4: 1578618800 | J4: 5.1314803e+09 | K4: =avg!I32/avg!H32 -> 3.2506139 | L4: =avg!U32/avg!N32 -> 1.593168 | M4: =avg!V32/avg!Q32 -> 6.9645128 | N4: =avg!W32/avg!R32 -> 0.31766639 | O4: =avg!T32/avg!K32 -> 52.038583 | P4: =avg!X4/avg!S4 -> 15.478042 | Q4: =avg!K32/avg!H32 -> 0.00051608406 | R4: =1-Q4-T4-U4 -> 0.95236293 | S4: =avg!N32/avg!H32 -> 0.85935545 | T4: =avg!Q32/avg!H32 -> 0.046337026 | U4: =avg!R32/avg!H32 -> 0.00078395536 | V4: =avg!T32/avg!I32 -> 0.008261911 | W4: =1-V4-Y4-Z4 -> 0.89238337 | X4: =avg!U32/avg!I32 -> 0.42118124 | Y4: =avg!V32/avg!I32 -> 0.099278111 | Z4: =avg!W32/avg!I32 -> 7.6612072e-05 | AA4: =W4-X4 -> 0.47120213 | AB4: =Y4/W4 -> 0.11125052
A5: 1048576 | B5: 5 | C5: 216 | D5: 0.95 | E5: 13 | F5: 16383 | G5: 16384 | H5: =A5/F5 -> 64.003906 | I5: 11699558900 | J5: 3.9534741e+10 | K5: =avg!I122/avg!H122 -> 3.3791651 | L5: =avg!U122/avg!N122 -> 1.8269684 | M5: =avg!V122/avg!Q122 -> 7.0827108 | N5: =avg!W122/avg!R122 -> 0.46019193 | O5: =avg!T122/avg!K122 -> 157.4559 | P5: =avg!X5/avg!S5 -> 9.9231164 | Q5: =avg!K122/avg!H122 -> 0.00045443594 | R5: =1-Q5-T5-U5 -> 0.94933589 | S5: =avg!N122/avg!H122 -> 0.80828927 | T5: =avg!Q122/avg!H122 -> 0.0495111 | U5: =avg!R122/avg!H122 -> 0.0006985705 | V5: =avg!T122/avg!I122 -> 0.02117494 | W5: =1-V5-Y5-Z5 -> 0.87495494 | X5: =avg!U122/avg!I122 -> 0.43700704 | Y5: =avg!V122/avg!I122 -> 0.10377498 | Z5: =avg!W122/avg!I122 -> 9.5134892e-05 | AA5: =W5-X5 -> 0.4379479 | AB5: =Y5/W5 -> 0.11860609
A6: 65536 | B6: 3 | C6: 64 | D6: 0.95 | E6: 10 | F6: 2047 | G6: 2049.3333 | H6: =A6/F6 -> 32.015633 | I6: 3.0051907e+08 | J6: 7.9890707e+08 | K6: =avg!I3/avg!H3 -> 2.6584239 | L6: =avg!U3/avg!N3 -> 0.85952265 | M6: =avg!V3/avg!Q3 -> 4.950433 | N6: =avg!W3/avg!R3 -> 0.21571938 | O6: =avg!T3/avg!K3 -> 19.340742 | P6: =avg!X6/avg!S6 -> 17.601191 | Q6: =avg!K3/avg!H3 -> 0.0024801532 | R6: =1-Q6-T6-U6 -> 0.91237084 | S6: =avg!N3/avg!H3 -> 0.80037828 | T6: =avg!Q3/avg!H3 -> 0.082783766 | U6: =avg!R3/avg!H3 -> 0.0023652409 | V6: =avg!T3/avg!I3 -> 0.018043776 | W6: =1-V6-Y6-Z6 -> 0.82760698 | X6: =avg!U3/avg!I3 -> 0.25877862 | Y6: =avg!V3/avg!I3 -> 0.15415731 | Z6: =avg!W3/avg!I3 -> 0.00019192887 | AA6: =W6-X6 -> 0.56882836 | AB6: =Y6/W6 -> 0.18626874
A7: 65536 | B7: 4 | C7: 125 | D7: 0.8 | E7: 10 | F7: 2047 | G7: 6705.3333 | H7: =A7/F7 -> 32.015633 | I7: 680044100 | J7: 2.4755987e+09 | K7: =avg!I4/avg!H4 -> 3.6403502 | L7: =avg!U4/avg!N4 -> 2.150968 | M7: =avg!V4/avg!Q4 -> 6.2106879 | N7: =avg!W4/avg!R4 -> 0.22077863 | O7: =avg!T4/avg!K4 -> 13.821224 | P7: =avg!X7/avg!S7 -> 14.343863 | Q7: =avg!K4/avg!H4 -> 0.0022951453 | R7: =1-Q7-T7-U7 -> 0.90261102 | S7: =avg!N4/avg!H4 -> 0.82134742 | T7: =avg!Q4/avg!H4 -> 0.094014834 | U7: =avg!R4/avg!H4 -> 0.0010789987 | V7: =avg!T4/avg!I4 -> 0.0087139192 | W7: =1-V7-Y7-Z7 -> 0.83082487 | X7: =avg!U4/avg!I4 -> 0.48530827 | Y7: =avg!V4/avg!I4 -> 0.16039577 | Z7: =avg!W4/avg!I4 -> 6.5438717e-05 | AA7: =W7-X7 -> 0.3455166 | AB7: =Y7/W7 -> 0.19305606
A8: 262144 | B8: 6 | C8: 343 | D8: 0.95 | E8: 10 | F8: 2047 | G8: 2048 | H8: =A8/F8 -> 128.06253 | I8: 5.8526226e+09 | J8: 1.3190028e+10 | K8: =avg!I66/avg!H66 -> 2.2536954 | L8: =avg!U66/avg!N66 -> 1.123191 | M8: =avg!V66/avg!Q66 -> 7.4916516 | N8: =avg!W66/avg!R66 -> 0.41662466 | O8: =avg!T66/avg!K66 -> 94.315107 | P8: =avg!X8/avg!S8 -> 13.090286 | Q8: =avg!K66/avg!H66 -> 0.00013259583 | R8: =1-Q8-T8-U8 -> 0.95095544 | S8: =avg!N66/avg!H66 -> 0.81463683 | T8: =avg!Q66/avg!H66 -> 0.048550394 | U8: =avg!R66/avg!H66 -> 0.0003615701 | V8: =avg!T66/avg!I66 -> 0.0055490151 | W8: =1-V8-Y8-Z8 -> 0.8329947 | X8: =avg!U66/avg!I66 -> 0.40599665 | Y8: =avg!V66/avg!I66 -> 0.16138944 | Z8: =avg!W66/avg!I66 -> 6.6840898e-05 | AA8: =W8-X8 -> 0.42699805 | AB8: =Y8/W8 -> 0.19374606
A9: 524288 | B9: 4 | C9: 125 | D9: 0.8 | E9: 13 | F9: 16383 | G9: 55018.667 | H9: =A9/F9 -> 32.001953 | I9: 4.5314254e+09 | J9: 2.0240341e+10 | K9: =avg!I95/avg!H95 -> 4.4666609 | L9: =avg!U95/avg!N95 -> 3.0719226 | M9: =avg!V95/avg!Q95 -> 6.7580102 | N9: =avg!W95/avg!R95 -> 0.45630595 | O9: =avg!T95/avg!K95 -> 40.603249 | P9: =avg!X9/avg!S9 -> 16.395847 | Q9: =avg!K95/avg!H95 -> 0.0029334184 | R9: =1-Q9-T9-U9 -> 0.88778652 | S9: =avg!N95/avg!H95 -> 0.71619251 | T9: =avg!Q95/avg!H95 -> 0.10835967 | U9: =avg!R95/avg!H95 -> 0.00092038735 | V9: =avg!T95/avg!I95 -> 0.026665628 | W9: =1-V9-Y9-Z9 -> 0.80929332 | X9: =avg!U95/avg!I95 -> 0.49255764 | Y9: =avg!V95/avg!I95 -> 0.16394702 | Z9: =avg!W95/avg!I95 -> 9.4025096e-05 | AA9: =W9-X9 -> 0.31673569 | AB9: =Y9/W9 -> 0.20258047
A10: 131072 | B10: 4 | C10: 125 | D10: 0.95 | E10: 11 | F10: 4095 | G10: 8192 | H10: =A10/F10 -> 32.007814 | I10: 7.8717473e+08 | J10: 3.0051593e+09 | K10: =avg!I33/avg!H33 -> 3.8176521 | L10: =avg!U33/avg!N33 -> 1.2235803 | M10: =avg!V33/avg!Q33 -> 6.7385611 | N10: =avg!W33/avg!R33 -> 0.27696522 | O10: =avg!T33/avg!K33 -> 30.123885 | P10: =avg!X10/avg!S10 -> 13.921046 | Q10: =avg!K33/avg!H33 -> 0.0017285446 | R10: =1-Q10-T10-U10 -> 0.90333633 | S10: =avg!N33/avg!H33 -> 0.7642382 | T10: =avg!Q33/avg!H33 -> 0.09329644 | U10: =avg!R33/avg!H33 -> 0.0016386874 | V10: =avg!T33/avg!I33 -> 0.013639399 | W10: =1-V10-Y10-Z10 -> 0.8215636 | X10: =avg!U33/avg!I33 -> 0.2449429 | Y10: =avg!V33/avg!I33 -> 0.16467812 | Z10: =avg!W33/avg!I33 -> 0.00011888444 | AA10: =W10-X10 -> 0.5766207 | AB10: =Y10/W10 -> 0.20044476
A11: 1048576 | B11: 4 | C11: 125 | D11: 0.95 | E11: 14 | F11: 32767 | G11: 65536 | H11: =A11/F11 -> 32.000977 | I11: 5915642300 | J11: 23327100800 | K11: =avg!I124/avg!H124 -> 3.9432913 | L11: =avg!U124/avg!N124 -> 1.4768298 | M11: =avg!V124/avg!Q124 -> 6.8504184 | N11: =avg!W124/avg!R124 -> 0.47343849 | O11: =avg!T124/avg!K124 -> 84.740793 | P11: =avg!X11/avg!S11 -> 15.802338 | Q11: =avg!K124/avg!H124 -> 0.0017446457 | R11: =1-Q11-T11-U11 -> 0.89852591 | S11: =avg!N124/avg!H124 -> 0.67196703 | T11: =avg!Q124/avg!H124 -> 0.098374074 | U11: =avg!R124/avg!H124 -> 0.0013553671 | V11: =avg!T124/avg!I124 -> 0.037492199 | W11: =1-V11-Y11-Z11 -> 0.79144632 | X11: =avg!U124/avg!I124 -> 0.2516631 | Y11: =avg!V124/avg!I124 -> 0.17089875 | Z11: =avg!W124/avg!I124 -> 0.00016272775 | AA11: =W11-X11 -> 0.53978322 | AB11: =Y11/W11 -> 0.21593221
A12: 524288 | B12: 3 | C12: 64 | D12: 0.95 | E12: 13 | F12: 16383 | G12: 16398.667 | H12: =A12/F12 -> 32.001953 | I12: 1.407393e+09 | J12: 5789837700 | K12: =avg!I92/avg!H92 -> 4.1138741 | L12: =avg!U92/avg!N92 -> 1.6782757 | M12: =avg!V92/avg!Q92 -> 6.6761182 | N12: =avg!W92/avg!R92 -> 0.44751835 | O12: =avg!T92/avg!K92 -> 25.946547 | P12: =avg!X12/avg!S12 -> 15.954 | Q12: =avg!K92/avg!H92 -> 0.0052825566 | R12: =1-Q12-T12-U12 -> 0.88243223 | S12: =avg!N92/avg!H92 -> 0.67673766 | T12: =avg!Q92/avg!H92 -> 0.10934619 | U12: =avg!R92/avg!H92 -> 0.0029390274 | V12: =avg!T92/avg!I92 -> 0.033317526 | W12: =1-V12-Y12-Z12 -> 0.78891248 | X12: =avg!U92/avg!I92 -> 0.27607855 | Y12: =avg!V92/avg!I92 -> 0.17745028 | Z12: =avg!W92/avg!I92 -> 0.00031971535 | AA12: =W12-X12 -> 0.51283393 | AB12: =Y12/W12 -> 0.22493024
A13: 1048576 | B13: 4 | C13: 125 | D13: 0.8 | E13: 14 | F13: 32767 | G13: 115997.33 | H13: =A13/F13 -> 32.000977 | I13: 8.2927996e+09 | J13: 3.7694101e+10 | K13: =avg!I126/avg!H126 -> 4.5454012 | L13: =avg!U126/avg!N126 -> 2.8897327 | M13: =avg!V126/avg!Q126 -> 6.8085216 | N13: =avg!W126/avg!R126 -> 0.44391418 | O13: =avg!T126/avg!K126 -> 35.212383 | P13: =avg!X13/avg!S13 -> 1.7991684 | Q13: =avg!K126/avg!H126 -> 0.0029302248 | R13: =1-Q13-T13-U13 -> 0.87082425 | S13: =avg!N126/avg!H126 -> 0.70859651 | T13: =avg!Q126/avg!H126 -> 0.12522892 | U13: =avg!R126/avg!H126 -> 0.0010166088 | V13: =avg!T126/avg!I126 -> 0.02269991 | W13: =1-V13-Y13-Z13 -> 0.78962137 | X13: =avg!U126/avg!I126 -> 0.45048928 | Y13: =avg!V126/avg!I126 -> 0.18757943 | Z13: =avg!W126/avg!I126 -> 9.9284323e-05 | AA13: =W13-X13 -> 0.3391321 | AB13: =Y13/W13 -> 0.23755617
A14: 131072 | B14: 4 | C14: 125 | D14: 0.8 | E14: 11 | F14: 4095 | G14: 14538.667 | H14: =A14/F14 -> 32.007814 | I14: 1.1605796e+09 | J14: 4.6640661e+09 | K14: =avg!I35/avg!H35 -> 4.0187386 | L14: =avg!U35/avg!N35 -> 2.3184144 | M14: =avg!V35/avg!Q35 -> 6.7563061 | N14: =avg!W35/avg!R35 -> 0.28757215 | O14: =avg!T35/avg!K35 -> 14.514472 | P14: =avg!X14/avg!S14 -> 2.1293398 | Q14: =avg!K35/avg!H35 -> 0.0025989025 | R14: =1-Q14-T14-U14 -> 0.88385487 | S14: =avg!N35/avg!H35 -> 0.78412738 | T14: =avg!Q35/avg!H35 -> 0.1123669 | U14: =avg!R35/avg!H35 -> 0.0011793245 | V14: =avg!T35/avg!I35 -> 0.0093864521 | W14: =1-V14-Y14-Z14 -> 0.80161785 | X14: =avg!U35/avg!I35 -> 0.45236389 | Y14: =avg!V35/avg!I35 -> 0.18891131 | Z14: =avg!W35/avg!I35 -> 8.4389884e-05 | AA14: =W14-X14 -> 0.34925396 | AB14: =Y14/W14 -> 0.23566255
A15: 65536 | B15: 4 | C15: 125 | D15: 0.65 | E15: 10 | F15: 2047 | G15: 11972 | H15: =A15/F15 -> 32.015633 | I15: 8.3684193e+08 | J15: 3728202800 | K15: =avg!I6/avg!H6 -> 4.455086 | L15: =avg!U6/avg!N6 -> 3.0146366 | M15: =avg!V6/avg!Q6 -> 6.7265992 | N15: =avg!W6/avg!R6 -> 0.19880542 | O15: =avg!T6/avg!K6 -> 9.1630927 | P15: =avg!X15/avg!S15 -> 11.379104 | Q15: =avg!K6/avg!H6 -> 0.00335842 | R15: =1-Q15-T15-U15 -> 0.86984914 | S15: =avg!N6/avg!H6 -> 0.80439086 | T15: =avg!Q6/avg!H6 -> 0.12592549 | U15: =avg!R6/avg!H6 -> 0.00086694986 | V15: =avg!T6/avg!I6 -> 0.0069075016 | W15: =1-V15-Y15-Z15 -> 0.80292273 | X15: =avg!U6/avg!I6 -> 0.54430961 | Y15: =avg!V6/avg!I6 -> 0.19013108 | Z15: =avg!W6/avg!I6 -> 3.8687094e-05 | AA15: =W15-X15 -> 0.25861312 | AB15: =Y15/W15 -> 0.23679873
A16: 524288 | B16: 4 | C16: 125 | D16: 0.65 | E16: 13 | F16: 16383 | G16: 101365.33 | H16: =A16/F16 -> 32.001953 | I16: 6.3575069e+09 | J16: 30943821500 | K16: =avg!I98/avg!H98 -> 4.8672887 | L16: =avg!U98/avg!N98 -> 3.8964595 | M16: =avg!V98/avg!Q98 -> 6.9835099 | N16: =avg!W98/avg!R98 -> 0.43629823 | O16: =avg!T98/avg!K98 -> 8.9389831 | P16: =avg!X16/avg!S16 -> 2.1384795 | Q16: =avg!K98/avg!H98 -> 0.004542399 | R16: =1-Q16-T16-U16 -> 0.85564371 | S16: =avg!N98/avg!H98 -> 0.73370212 | T16: =avg!Q98/avg!H98 -> 0.1391551 | U16: =avg!R98/avg!H98 -> 0.00065879074 | V16: =avg!T98/avg!I98 -> 0.0083423094 | W16: =1-V16-Y16-Z16 -> 0.79194107 | X16: =avg!U98/avg!I98 -> 0.58735793 | Y16: =avg!V98/avg!I98 -> 0.19965757 | Z16: =avg!W98/avg!I98 -> 5.9053253e-05 | AA16: =W16-X16 -> 0.20458314 | AB16: =Y16/W16 -> 0.25211164
A17: 262144 | B17: 4 | C17: 125 | D17: 0.8 | E17: 12 | F17: 8191 | G17: 32648 | H17: =A17/F17 -> 32.003907 | I17: 2659528400 | J17: 9.5858614e+09 | K17: =avg!I67/avg!H67 -> 3.6043463 | L17: =avg!U67/avg!N67 -> 2.6809579 | M17: =avg!V67/avg!Q67 -> 6.7141291 | N17: =avg!W67/avg!R67 -> 0.3955184 | O17: =avg!T67/avg!K67 -> 15.064173 | P17: =avg!X17/avg!S17 -> 2.4883281 | Q17: =avg!K67/avg!H67 -> 0.00227692 | R17: =1-Q17-T17-U17 -> 0.8874226 | S17: =avg!N67/avg!H67 -> 0.58609628 | T17: =avg!Q67/avg!H67 -> 0.1094805 | U17: =avg!R67/avg!H67 -> 0.00081998247 | V17: =avg!T67/avg!I67 -> 0.0095162653 | W17: =1-V17-Y17-Z17 -> 0.78645491 | X17: =avg!U67/avg!I67 -> 0.43594575 | Y17: =avg!V67/avg!I67 -> 0.20393884 | Z17: =avg!W67/avg!I67 -> 8.9979742e-05 | AA17: =W17-X17 -> 0.35050916 | AB17: =Y17/W17 -> 0.25931409
A18: 262144 | B18: 5 | C18: 216 | D18: 0.95 | E18: 11 | F18: 4095 | G18: 8192 | H18: =A18/F18 -> 64.015629 | I18: 3.2021934e+09 | J18: 8.7284289e+09 | K18: =avg!I65/avg!H65 -> 2.7257657 | L18: =avg!U65/avg!N65 -> 1.0626007 | M18: =avg!V65/avg!Q65 -> 7.1375485 | N18: =avg!W65/avg!R65 -> 0.39744518 | O18: =avg!T65/avg!K65 -> 61.32066 | P18: =avg!X18/avg!S18 -> 3.0932442 | Q18: =avg!K65/avg!H65 -> 0.00043068396 | R18: =1-Q18-T18-U18 -> 0.91047714 | S18: =avg!N65/avg!H65 -> 0.63357599 | T18: =avg!Q65/avg!H65 -> 0.088416626 | U18: =avg!R65/avg!H65 -> 0.00067554738 | V18: =avg!T65/avg!I65 -> 0.0096889563 | W18: =1-V18-Y18-Z18 -> 0.75868936 | X18: =avg!U65/avg!I65 -> 0.24699052 | Y18: =avg!V65/avg!I65 -> 0.23152318 | Z18: =avg!W65/avg!I65 -> 9.8501881e-05 | AA18: =W18-X18 -> 0.51169884 | AB18: =Y18/W18 -> 0.30516202
A19: 262144 | B19: 4 | C19: 125 | D19: 0.95 | E19: 12 | F19: 8191 | G19: 24481.333 | H19: =A19/F19 -> 32.003907 | I19: 1528670700 | J19: 6.2023871e+09 | K19: =avg!I62/avg!H62 -> 4.0573729 | L19: =avg!U62/avg!N62 -> 1.1608981 | M19: =avg!V62/avg!Q62 -> 6.804065 | N19: =avg!W62/avg!R62 -> 0.39037834 | O19: =avg!T62/avg!K62 -> 26.862075 | P19: =avg!X19/avg!S19 -> 0.78387712 | Q19: =avg!K62/avg!H62 -> 0.0021866275 | R19: =1-Q19-T19-U19 -> 0.85510381 | S19: =avg!N62/avg!H62 -> 0.70824091 | T19: =avg!Q62/avg!H62 -> 0.14128543 | U19: =avg!R62/avg!H62 -> 0.0014241349 | V19: =avg!T62/avg!I62 -> 0.014476695 | W19: =1-V19-Y19-Z19 -> 0.74845582 | X19: =avg!U62/avg!I62 -> 0.20264234 | Y19: =avg!V62/avg!I62 -> 0.23693046 | Z19: =avg!W62/avg!I62 -> 0.00013702251 | AA19: =W19-X19 -> 0.54581347 | AB19: =Y19/W19 -> 0.31655905
A20: 1048576 | B20: 5 | C20: 216 | D20: 0.8 | E20: 13 | F20: 16383 | G20: 59337.333 | H20: =A20/F20 -> 64.003906 | I20: 1.5283255e+10 | J20: 60313237600 | K20: =avg!I127/avg!H127 -> 3.9463607 | L20: =avg!U127/avg!N127 -> 2.4018422 | M20: =avg!V127/avg!Q127 -> 7.2902442 | N20: =avg!W127/avg!R127 -> 0.46575943 | O20: =avg!T127/avg!K127 -> 68.570968 | P20: =avg!X20/avg!S20 -> 1.691606 | Q20: =avg!K127/avg!H127 -> 0.00080226583 | R20: =1-Q20-T20-U20 -> 0.86640022 | S20: =avg!N127/avg!H127 -> 0.75796517 | T20: =avg!Q127/avg!H127 -> 0.13226557 | U20: =avg!R127/avg!H127 -> 0.00053193729 | V20: =avg!T127/avg!I127 -> 0.013939969 | W20: =1-V20-Y20-Z20 -> 0.74165863 | X20: =avg!U127/avg!I127 -> 0.46131432 | Y20: =avg!V127/avg!I127 -> 0.24433862 | Z20: =avg!W127/avg!I127 -> 6.2780579e-05 | AA20: =W20-X20 -> 0.28034431 | AB20: =Y20/W20 -> 0.3294489
A21: 131072 | B21: 5 | C21: 216 | D21: 0.8 | E21: 10 | F21: 2047 | G21: 7340 | H21: =A21/F21 -> 64.031265 | I21: 2538790400 | J21: 7.347832e+09 | K21: =avg!I37/avg!H37 -> 2.8942255 | L21: =avg!U37/avg!N37 -> 2.1708075 | M21: =avg!V37/avg!Q37 -> 7.2037512 | N21: =avg!W37/avg!R37 -> 0.26341017 | O21: =avg!T37/avg!K37 -> 23.695867 | P21: =avg!X21/avg!S21 -> 3.6982597 | Q21: =avg!K37/avg!H37 -> 0.00064777568 | R21: =1-Q21-T21-U21 -> 0.90012666 | S21: =avg!N37/avg!H37 -> 0.62046839 | T21: =avg!Q37/avg!H37 -> 0.098694166 | U21: =avg!R37/avg!H37 -> 0.00053139479 | V21: =avg!T37/avg!I37 -> 0.0053035281 | W21: =1-V21-Y21-Z21 -> 0.74899752 | X21: =avg!U37/avg!I37 -> 0.46538095 | Y21: =avg!V37/avg!I37 -> 0.24565059 | Z21: =avg!W37/avg!I37 -> 4.8363472e-05 | AA21: =W21-X21 -> 0.28361657 | AB21: =Y21/W21 -> 0.3279725
A22: 131072 | B22: 4 | C22: 125 | D22: 0.65 | E22: 11 | F22: 4095 | G22: 30177.333 | H22: =A22/F22 -> 32.007814 | I22: 2055697300 | J22: 7.1058797e+09 | K22: =avg!I38/avg!H38 -> 3.4566761 | L22: =avg!U38/avg!N38 -> 3.2196939 | M22: =avg!V38/avg!Q38 -> 6.7908882 | N22: =avg!W38/avg!R38 -> 0.32527155 | O22: =avg!T38/avg!K38 -> 7.4241122 | P22: =avg!X22/avg!S22 -> 3.3240359 | Q22: =avg!K38/avg!H38 -> 0.0026981437 | R22: =1-Q22-T22-U22 -> 0.86767664 | S22: =avg!N38/avg!H38 -> 0.5340948 | T22: =avg!Q38/avg!H38 -> 0.12901912 | U22: =avg!R38/avg!H38 -> 0.00060608794 | V22: =avg!T38/avg!I38 -> 0.0057949663 | W22: =1-V22-Y22-Z22 -> 0.74068067 | X22: =avg!U38/avg!I38 -> 0.49747842 | Y22: =avg!V38/avg!I38 -> 0.25346733 | Z22: =avg!W38/avg!I38 -> 5.7032582e-05 | AA22: =W22-X22 -> 0.24320226 | AB22: =Y22/W22 -> 0.34220864
A23: 1048576 | B23: 4 | C23: 125 | D23: 0.65 | E23: 14 | F23: 32767 | G23: 250256 | H23: =A23/F23 -> 32.000977 | I23: 1.1804671e+10 | J23: 5.9211002e+10 | K23: =avg!I129/avg!H129 -> 5.0158958 | L23: =avg!U129/avg!N129 -> 3.7583109 | M23: =avg!V129/avg!Q129 -> 6.9412555 | N23: =avg!W129/avg!R129 -> 0.48283225 | O23: =avg!T129/avg!K129 -> 17.418376 | P23: =avg!X23/avg!S23 -> 2.4479284 | Q23: =avg!K129/avg!H129 -> 0.0041565805 | R23: =1-Q23-T23-U23 -> 0.8103951 | S23: =avg!N129/avg!H129 -> 0.69434586 | T23: =avg!Q129/avg!H129 -> 0.18477913 | U23: =avg!R129/avg!H129 -> 0.00066918424 | V23: =avg!T129/avg!I129 -> 0.014434287 | W23: =1-V23-Y23-Z23 -> 0.7297944 | X23: =avg!U129/avg!I129 -> 0.52025953 | Y23: =avg!V129/avg!I129 -> 0.2557069 | Z23: =avg!W129/avg!I129 -> 6.4415957e-05 | AA23: =W23-X23 -> 0.20953487 | AB23: =Y23/W23 -> 0.35038211
